<?xml version="1.0"?>
<robot xmlns:xacro="http://www.ros.org/wiki/xacro">

<material name="white">
  <color rgba="1 1 1 1" />
</material>
<material name="orange">
  <color rgba="1 0.3 0.1 1"/>
</material>
<material name="blue">
  <color rgba="0.2 0.2 1 1"/>
</material>
<material name="black">
  <color rgba="0 0 0 1"/>
</material>
<material name="red">
  <color rgba="1 0 0 1"/>
</material>

  <!-- ===== INCLUDE INERTIAL MACROS ===== -->
  <xacro:include filename="inertial_macros.xacro"/>

  <!-- ===== ROBOT CORE ===== -->
  <xacro:macro name="robot_core" params="prefix">

    <!-- ===== BASE LINK ===== -->
    <link name="${prefix}base_link"/>

    <!-- ===== BASE FOOTPRINT ===== -->
    <joint name="${prefix}base_footprint_joint" type="fixed">
      <parent link="${prefix}base_link"/>
      <child link="${prefix}base_footprint"/>
      <origin xyz="0 0 0" rpy="0 0 0"/>
    </joint>

    <link name="${prefix}base_footprint"/>

    <!-- ===== CHASSIS ===== -->
    <joint name="${prefix}chassis_joint" type="fixed">
      <parent link="${prefix}base_link"/>
      <child link="${prefix}chassis"/>
      <origin xyz="0 0 0" rpy="0 0 0"/>
    </joint>

    <link name="${prefix}chassis">
      <visual>
        <origin xyz="0 0 0.075" rpy="0 0 0"/>
        <geometry>
          <cylinder radius="0.11" length="0.15"/>
        </geometry>
        <material name="white"/>
      </visual>
      <collision>
        <origin xyz="0 0 0.075" rpy="0 0 0"/>
        <geometry>
          <cylinder radius="0.11" length="0.15"/>
        </geometry>
      </collision>

      <xacro:inertial_cylinder
        mass="1.3"
        length="0.15"
        radius="0.11">
        <origin xyz="0 0 0.075" rpy="0 0 0"/>
      </xacro:inertial_cylinder>
    </link>

    <!-- ===== LEFT WHEEL ===== -->
    <joint name="${prefix}left_wheel_joint" type="continuous">
      <parent link="${prefix}base_link"/>
      <child link="${prefix}left_wheel"/>
      <origin xyz="0 0.0875 0.0235" rpy="-${pi/2} 0 0"/>
      <axis xyz="0 0 1"/>
    </joint>

    <link name="${prefix}left_wheel">
      <visual>
        <geometry>
          <cylinder radius="0.0325" length="0.025"/>
        </geometry>
        <material name="blue"/>
      </visual>
      <collision>
        <geometry>
          <cylinder radius="0.0325" length="0.025"/>
        </geometry>
        <surface>
          <friction>
            <ode>
              <mu>1.0</mu>
              <mu2>1.0</mu2>
            </ode>
          </friction>
        </surface>  
      </collision>

      <xacro:inertial_cylinder
        mass="0.05"
        length="0.025"
        radius="0.0325">
        <origin xyz="0 0 0" rpy="0 0 0"/>
      </xacro:inertial_cylinder>
    </link>

    <!-- ===== RIGHT WHEEL ===== -->
    <joint name="${prefix}right_wheel_joint" type="continuous">
      <parent link="${prefix}base_link"/>
      <child link="${prefix}right_wheel"/>
      <origin xyz="0 -0.0875 0.0235" rpy="${pi/2} 0 0"/>
      <axis xyz="0 0 -1"/>
    </joint>

    <link name="${prefix}right_wheel">
      <visual>
        <geometry>
          <cylinder radius="0.0325" length="0.025"/>
        </geometry>
        <material name="blue"/>
      </visual>
      <collision>
        <geometry>
          <cylinder radius="0.0325" length="0.025"/>
        </geometry>
        <surface>
          <friction>
            <ode>
              <mu>1.0</mu>
              <mu2>1.0</mu2>
            </ode>
          </friction>
        </surface>  
      </collision>

      <xacro:inertial_cylinder
        mass="0.05"
        length="0.025"
        radius="0.0325">
        <origin xyz="0 0 0" rpy="0 0 0"/>
      </xacro:inertial_cylinder>
    </link>

    <!-- ===== CASTER WHEEL ===== -->
    <joint name="${prefix}caster_wheel_joint" type="fixed">
      <parent link="${prefix}chassis"/>
      <child link="${prefix}caster_wheel"/>
      <origin xyz="0.08 0 0.001" rpy="0 0 0"/>
    </joint>

    <link name="${prefix}caster_wheel">
      <visual>
        <geometry>
          <sphere radius="0.01"/>
        </geometry>
        <material name="black"/>
      </visual>

      <collision>
        <geometry>
          <sphere radius="0.01"/>
        </geometry>
        <surface>
          <friction>
            <ode>
              <mu>0.0</mu>
              <mu2>0.0</mu2>
            </ode>
          </friction>
        </surface>
      </collision>

      <xacro:inertial_sphere mass="0.2" radius="0.01">
        <origin xyz="0 0 0" rpy="0 0 0"/>
      </xacro:inertial_sphere>
    </link>

    <!-- ===== TRANSMISSIONS ===== -->
    <transmission name="${prefix}left_wheel_trans">
      <type>transmission_interface/SimpleTransmission</type>

      <joint name="${prefix}left_wheel_joint">
        <hardwareInterface>hardware_interface/PositionJointInterface</hardwareInterface>
      </joint>

      <actuator name="${prefix}left_wheel_motor">
        <mechanicalReduction>1</mechanicalReduction>
      </actuator>
    </transmission>


    <transmission name="${prefix}right_wheel_trans">
      <type>transmission_interface/SimpleTransmission</type>

      <joint name="${prefix}right_wheel_joint">
        <hardwareInterface>hardware_interface/PositionJointInterface</hardwareInterface>
      </joint>

      <actuator name="${prefix}right_wheel_motor">
        <mechanicalReduction>1</mechanicalReduction>
      </actuator>
    </transmission>

  </xacro:macro>

</robot>
